Workbook

Sheet cashflow
A1: Finance >>Cash Flow (Standalone)>>Dabur India Ltd(Curr. Rs in )
A2: Year | B2: 202503 | C2: 202403 | D2: 202303 | E2: 202203 | F2: 202103 | G2: 202003 | H2: 201903 | I2: 201803 | J2: 201703 | K2: 201603
A3: Cash Flow Summary
A4: Cash and Cash Equivalents at Beginning of the year | B4: 10.77 | C4: 15.35 | D4: 10.47 | E4: 7.01 | F4: -21.75 | G4: -20.24 | H4: 57.8 | I4: -1.25 | J4: 24.41 | K4: 13.49
A5: Net Cash from Operating Activities | B5: 1622.97 | C5: 1653.33 | D5: 1561.91 | E5: 1319.95 | F5: 1704.17 | G5: 1154.77 | H5: 1123.57 | I5: 816.41 | J5: 926.94 | K5: 960.3
A6: Net Profit before Tax & Extraordinary Items | B6: 1808.34 | C6: 1966.7 | D6: 1828.67 | E6: 1896.31 | F6: 1683.31 | G6: 1408.47 | H6: 1503.35 | I6: 1373.13 | J6: 1294.35 | K6: 1209.35
A7: Depreciation | B7: 250.93 | C7: 208.86 | D7: 188.29 | E7: 160.39 | F7: 143.4 | G7: 129.93 | H7: 108.83 | I7: 102.5 | J7: 75.43 | K7: 72.83
A8: Interest (Net) | B8: -205.45 | C8: -236.1 | D8: -251.66 | E8: -248.27 | F8: -213.09 | G8: -196.35 | H8: -202.77 | I8: -200.44 | J8: -187.91 | K8: -151.07
A9: Dividend Received | B9: 0 | C9: 0 | D9: 0 | E9: 0 | F9: 0 | G9: 0 | H9: 0 | I9: 0 | J9: 0 | K9: 0
A10: P/L on Sales of Assets | B10: 1.27 | C10: 1.34 | D10: -16.53 | E10: 0.68 | F10: -0.33 | G10: 1.76 | H10: -0.89 | I10: -2.42 | J10: 0.86 | K10: -3.78
A11: P/L on Sales of Invest | B11: 0 | C11: 0 | D11: 0 | E11: 0 | F11: -0.42 | G11: 0 | H11: 0 | I11: 0 | J11: 0 | K11: -21.53
A12: Prov. & W/O (Net) | B12: 13.25 | C12: 25.67 | D12: 9.73 | E12: -8.7 | F12: 22.82 | G12: 14.98 | H12: 11.44 | I12: 14.87 | J12: 9.46 | K12: 7.38
A13: P/L in Forex | B13: 2.57 | C13: -0.02 | D13: 0.05 | E13: -1.24 | F13: 1.11 | G13: -3.7 | H13: 2.93 | I13: 1.77 | J13: 0.87 | K13: 2.14
A14: Fin. Lease & Rental Chrgs | B14: 0 | C14: 0 | D14: 0 | E14: 0 | F14: 0 | G14: 0 | H14: 0 | I14: 0 | J14: 0 | K14: 0
A15: Others | B15: -91.82 | C15: -12.13 | D15: 54.28 | E15: 14 | F15: 7.41 | G15: 109.68 | H15: 55.07 | I15: -18.63 | J15: -46.19 | K15: 45
... A60: Cash and Cash Equivalents at End of the year | B60: 24.16 | C60: 10.77 | D60: 15.35 | E60: 10.47 | F60: 7.01 | G60: -21.75 | H60: -20.24 | I60: 57.8 | J60: -1.25 | K60: 24.42

Sheet Bal.sheet
A1: Finance >>Balance Sheet (Standalone)>>Dabur India Ltd(Curr. in )
A2: Year | B2: 201603 | C2: 201703 | D2: 201803 | E2: 201903 | F2: 202003 | G2: 202103 | H2: 202203 | I2: 202303 | J2: 202403 | K2: 202503
A3: SOURCES OF FUNDS :
A4: Share Capital | B4: 175.91 | C4: 176.15 | D4: 176.15 | E4: 176.63 | F4: 176.71 | G4: 176.74 | H4: 176.79 | I4: 177.18 | J4: 177.2 | K4: 177.23
A5: Reserves Total | B5: 2918.38 | C5: 3481.73 | D5: 4050.71 | E5: 3792.19 | F5: 4397.52 | G5: 5214.48 | H5: 5687.08 | I5: 6109.7 | J5: 6738.17 | K5: 7246.06
A8: Total Shareholders Funds | B8: 3094.29 | C8: 3657.88 | D8: 4226.86 | E8: 3968.82 | F8: 4574.23 | G8: 5391.22 | H8: 5863.87 | I8: 6286.88 | J8: 6915.37 | K8: 7423.29
A9: Secured Loans | B9: 7.68 | C9: 209.07 | D9: 208.6 | E9: 227.73 | F9: 101.19 | G9: 26.94 | H9: 0 | I9: 177.76 | J9: 99.99 | K9: 0.1
A10: Unsecured Loans | B10: 79.55 | C10: 74.68 | D10: 78.01 | E10: 82.13 | F10: 49.46 | G10: 152.93 | H10: 560.18 | I10: 437.7 | J10: 675.97 | K10: 378.62
A11: Total Debt | B11: 87.23 | C11: 283.75 | D11: 286.61 | E11: 309.86 | F11: 150.65 | G11: 179.87 | H11: 560.18 | I11: 615.46 | J11: 775.96 | K11: 378.72
A12: Other Liabilities | B12: 49.99 | C12: 51.23 | D12: 54.29 | E12: 57.32 | F12: 59.35 | G12: 56.92 | H12: 60.82 | I12: 62.62 | J12: 65.63 | K12: 64.49
A13: Total Liabilities | B13: 3231.51 | C13: 3992.86 | D13: 4567.76 | E13: 4336 | F13: 4784.23 | G13: 5628.01 | H13: 6484.87 | I13: 6964.96 | J13: 7756.96 | K13: 7866.5
A14: APPLICATION OF FUNDS :
A15: Gross Block | B15: 1131.34 | C15: 1549.58 | D15: 1671.38 | E15: 1774.43 | F15: 1982.29 | G15: 2168.03 | H15: 2501.1 | I15: 2937.65 | J15: 3345.31 | K15: 3722.26
A16: Less : Accumulated Depreciation | B16: 492.53 | C16: 556.25 | D16: 640.9 | E16: 737.81 | F16: 848.01 | G16: 963.22 | H16: 1102.1 | I16: 1275.68 | J16: 1467.11 | K16: 1686.64
A17: Less:Impairment of Assets | B17: 0 | C17: 0 | D17: 0 | E17: 0 | F17: 0 | G17: 0 | H17: 0 | I17: 0 | J17: 0 | K17: 0
A18: Net Block | B18: 638.81 | C18: 993.33 | D18: 1030.48 | E18: 1036.62 | F18: 1134.28 | G18: 1204.81 | H18: 1399 | I18: 1661.97 | J18: 1878.2 | K18: 2035.62
A21: Capital Work in Progress | B21: 24.96 | C21: 28.25 | D21: 26.82 | E21: 21.69 | F21: 105.83 | G21: 107.26 | H21: 128.48 | I21: 109.43 | J21: 184.23 | K21: 136.88
A22: Producing Properties | B22: 0 | C22: 0 | D22: 0 | E22: 0 | F22: 0 | G22: 0 | H22: 0 | I22: 0 | J22: 0 | K22: 0
A23: Investments | B23: 2570.31 | C23: 3054.15 | D23: 3433.06 | E23: 2962.14 | F23: 2466.83 | G23: 3573.9 | H23: 5007.08 | I23: 5475.05 | J23: 6148.47 | K23: 6358.82
A24: Current Assets, Loans & Advances
A25: Inventories | B25: 615.56 | C25: 599.27 | D25: 704.79 | E25: 732.9 | F25: 809.14 | G25: 1114.16 | H25: 1237.96 | I25: 1223.77 | J25: 1149.88 | K25: 1288.07
A26: Sundry Debtors | B26: 420.69 | C26: 333.25 | D26: 321.34 | E26: 431.46 | F26: 379.63 | G26: 281.24 | H26: 454.55 | I26: 561.18 | J26: 719.21 | K26: 600.58
A27: Cash and Bank | B27: 55.63 | C27: 26.16 | D27: 87.02 | E27: 124.71 | F27: 525.6 | G27: 834.74 | H27: 136.18 | I27: 33.4 | J27: 71.11 | K27: 133.02
A28: Loans and Advances | B28: 68.26 | C28: 91.81 | D28: 132.3 | E28: 109.88 | F28: 168.15 | G28: 148.71 | H28: 126.06 | I28: 140.4 | J28: 232 | K28: 280.07
A29: Total Current Assets | B29: 1160.14 | C29: 1050.49 | D29: 1245.45 | E29: 1398.95 | F29: 1882.52 | G29: 2378.85 | H29: 1954.75 | I29: 1958.75 | J29: 2172.2 | K29: 2301.74
A30: Less : Current Liabilities and Provisions | U30: 1003.15 | V30: 971.62 | W30: 937.19 | X30: 789.76
A31: Current Liabilities | B31: 1070.85 | C31: 1061.37 | D31: 1080.62 | E31: 1145.54 | F31: 1188.38 | G31: 1715.09 | H31: 1844.16 | I31: 2108.21 | J31: 2396.79 | K31: 2663.03 | U31: 998.32 | V31: 960.62 | W31: 914.52 | X31: 784.88
A32: Provisions | B32: 50.85 | C32: 64.51 | D32: 68.29 | E32: 88.92 | F32: 127.5 | G32: 161.06 | H32: 192.93 | I32: 202.51 | J32: 278.56 | K32: 342.69 | U32: 4.83 | V32: 11 | W32: 22.67 | X32: 4.88
A33: Total Current Liabilities | B33: 1121.7 | C33: 1125.88 | D33: 1148.91 | E33: 1234.46 | F33: 1315.88 | G33: 1876.15 | H33: 2037.09 | I33: 2310.72 | J33: 2675.35 | K33: 3005.72 | U33: 0 | V33: 0 | W33: 0 | X33: 0
A34: Net Current Assets | B34: 38.44 | C34: -75.39 | D34: 96.54 | E34: 164.49 | F34: 566.64 | G34: 502.7 | H34: -82.34 | I34: -351.97 | J34: -503.15 | K34: -703.98 | U34: 0 | V34: 0 | W34: 0 | X34: 0
U35: 0 | V35: 0 | W35: 0 | X35: 146.46
A36: Deferred Tax Assets | B36: 13.22 | C36: 5.79 | D36: 17.8 | E36: 102.61 | F36: 151.29 | G36: 148.95 | H36: 78.32 | I36: 100.24 | J36: 103.66 | K36: 89.68 | U36: 0 | V36: 0 | W36: 0 | X36: 0
A37: Deferred Tax Liability | B37: 89.74 | C37: 104.07 | D37: 113.83 | E37: 110.93 | F37: 129.67 | G37: 131.5 | H37: 148.36 | I37: 177 | J37: 204.16 | K37: 222.93 | U37: 0 | V37: 0 | W37: 0 | X37: 0
A38: Net Deferred Tax | B38: -76.52 | C38: -98.28 | D38: -96.03 | E38: -8.32 | F38: 21.62 | G38: 17.45 | H38: -70.04 | I38: -76.76 | J38: -100.5 | K38: -133.25 | U38: 0 | V38: 0 | W38: 0 | X38: 0
A39: Other Assets | B39: 35.51 | C39: 90.8 | D39: 76.89 | E39: 159.38 | F39: 489.03 | G39: 221.89 | H39: 102.69 | I39: 147.24 | J39: 149.71 | K39: 172.41 | U39: 19.7 | V39: 12.79 | W39: 12.32 | X39: 7.24
A40: Long-Term Loans and Advances | B40: 33.97 | C40: 16.2 | D40: 22.8 | E40: 91.64 | F40: 420.91 | G40: 108.99 | H40: 23.15 | I40: 75.48 | J40: 56.98 | K40: 40.91 | U40: 0 | V40: 0 | W40: 0 | X40: 0
A41: Other Non-Current Assets | B41: 1.54 | C41: 74.6 | D41: 54.09 | E41: 67.74 | F41: 68.12 | G41: 112.9 | H41: 79.51 | I41: 71.76 | J41: 92.73 | K41: 131.5 | U41: 0.91 | V41: 1.41 | W41: 2.1 | X41: 0.87
A42: Others | B42: 0 | C42: 0 | D42: 0 | E42: 0 | F42: 0 | G42: 0 | H42: 0.03 | I42: 0 | J42: 0 | K42: 0 | U42: 9.47 | V42: 6.56 | W42: 6.35 | X42: 5.7
A43: Total Assets | B43: 3231.51 | C43: 3992.86 | D43: 4567.76 | E43: 4336 | F43: 4784.23 | G43: 5628.01 | H43: 6484.87 | I43: 6964.96 | J43: 7756.96 | K43: 7866.5 | U43: 0.89 | V43: 0.93 | W43: 0.75 | X43: 0
A44: Contingent Liabilities | B44: 1183.31 | C44: 1055.31 | D44: 846.63 | E44: 536.74 | F44: 222.88 | G44: 241.7 | H44: 253.92 | I44: 248.38 | J44: 221.08 | K44: 562.3 | U44: 111.42 | V44: 87.31 | W44: 102.66 | X44: 120.82

Sheet PL
A1: Finance >>Profit & Loss (Standalone)>>Dabur India Ltd(Curr. in )
A2: Year | B2: 202503 | C2: 202403 | D2: 202303 | E2: 202203 | F2: 202103 | G2: 202003 | H2: 201903 | I2: 201803 | J2: 201703 | K2: 201603
A3: INCOME :
A4: Sales Turnover | B4: 9070.71 | C4: 9135.6 | D4: 8684.35 | E4: 8179.5 | F4: 7184.73 | G4: 6309.8 | H4: 6273.19 | I4: 5609.06 | J4: 5369.84 | K4: 5422.57
A5: Net Sales | B5: 9070.71 | C5: 9135.6 | D5: 8684.35 | E5: 8179.5 | F5: 7184.73 | G5: 6309.8 | H5: 6273.19 | I5: 5592.29 | J5: 5290.65 | K5: 5340.04
A6: Other Income | B6: 451.94 | C6: 417.62 | D6: 392.17 | E6: 341.55 | F6: 276.65 | G6: 276.9 | H6: 274.74 | I6: 283.23 | J6: 274.64 | K6: 194.36
A7: Stock Adjustments | B7: -12.9 | C7: -49.18 | D7: 24.98 | E7: 28.49 | F7: 176.71 | G7: 69.89 | H7: -10.09 | I7: 74.03 | J7: 8.19 | K7: 23.77
A8: Total Income | B8: 9509.75 | C8: 9504.04 | D8: 9101.5 | E8: 8549.54 | F8: 7638.09 | G8: 6656.59 | H8: 6537.84 | I8: 5949.55 | J8: 5573.48 | K8: 5558.17
A9: EXPENDITURE :
A10: Raw Materials | B10: 3896.24 | C10: 3797.27 | D10: 3797.74 | E10: 3444.55 | F10: 3065.28 | G10: 2531.18 | H10: 2511.23 | I10: 2281.22 | J10: 2129.17 | K10: 2150.59
A11: Power & Fuel Cost | B11: 97.85 | C11: 99.23 | D11: 93.32 | E11: 85.02 | F11: 70.72 | G11: 66.48 | H11: 63.99 | I11: 59.43 | J11: 50.61 | K11: 47.77
A12: Employee Cost | B12: 776.86 | C12: 782.14 | D12: 725.96 | E12: 678.71 | F12: 655.82 | G12: 578.26 | H12: 572.33 | I12: 461.13 | J12: 425.3 | K12: 431.89
A13: Other Manufacturing Expenses | B13: 1165.16 | C13: 1192.6 | D13: 1199.1 | E13: 1049.95 | F13: 880.46 | G13: 854.86 | H13: 804.04 | I13: 756.51 | J13: 732.62 | K13: 716.49
A14: Selling and Administration Expenses | B14: 1267.24 | C14: 1228.56 | D14: 1021.29 | E14: 1068.62 | F14: 1002.15 | G14: 847.58 | H14: 835 | I14: 776.29 | J14: 748.55 | K14: 733.72
A15: Miscellaneous Expenses | B15: 147.55 | C15: 147.54 | D15: 200.76 | E15: 147.32 | F15: 127.81 | G15: 220.56 | H15: 109.27 | I15: 117.45 | J15: 101.22 | K15: 185.27
A17: Total Expenditure | B17: 7350.9 | C17: 7247.34 | D17: 7038.17 | E17: 6474.17 | F17: 5802.24 | G17: 5098.92 | H17: 4895.86 | I17: 4452.03 | J17: 4187.47 | K17: 4265.73
A18: Operating Profit | B18: 2158.85 | C18: 2256.7 | D18: 2063.33 | E18: 2075.37 | F18: 1835.85 | G18: 1557.67 | H18: 1641.98 | I18: 1497.52 | J18: 1386.01 | K18: 1292.44
A19: Interest | B19: 99.58 | C19: 81.14 | D19: 46.37 | E19: 18.67 | F19: 9.14 | G19: 19.27 | H19: 29.8 | I19: 21.89 | J19: 16.23 | K19: 10.26
A20: Gross Profit | B20: 2059.27 | C20: 2175.56 | D20: 2016.96 | E20: 2056.7 | F20: 1826.71 | G20: 1538.4 | H20: 1612.18 | I20: 1475.63 | J20: 1369.78 | K20: 1282.18
A21: Depreciation | B21: 250.93 | C21: 208.86 | D21: 188.29 | E21: 160.39 | F21: 143.4 | G21: 129.93 | H21: 108.83 | I21: 102.5 | J21: 75.43 | K21: 72.83
A22: Profit Before Tax | B22: 1808.34 | C22: 1966.7 | D22: 1828.67 | E22: 1896.31 | F22: 1683.31 | G22: 1408.47 | H22: 1503.35 | I22: 1373.13 | J22: 1294.35 | K22: 1209.35
... A42: Dividend Per Share Adj.(Rs) | B42: 8 | C42: 5.5 | D42: 5.2 | E42: 5.2 | F42: 4.75 | G42: 3 | H42: 2.75 | I42: 7.5 | J42: 2.25 | K42: 2.25

Sheet sources
A3: 1 | B3: Actual Financial Statement data for last 5 years
B4: Revenue Growth | C4: 0.013 | D4: As mentioned in Annual Report 2025 | E4: chrome-extension://efaidnbmnnnibpcajpcglclefindmkaj/https://www.dabur.com/Investors/Financial%20Information/Reports/Annual%20Reports/2024-25/Dabur%20India%20Limited%20Annual%20Report%202024-25.pdf?utm_
A5: 2 | B5: Tax Rate | C5: 0.3494 | D5: As mentioned in Annual Report 2025 | E5: chrome-extension://efaidnbmnnnibpcajpcglclefindmkaj/https://www.dabur.com/Investors/Financial%20Information/Reports/Annual%20Reports/2024-25/Dabur%20India%20Limited%20Annual%20Report%202024-25.pdf?utm_
A6: 3 | B6: Data period used for Stock and Market Index Price
A7: 4 | B7: Risk Free Rate | C7: 0.0737
A8: 5 | B8: Market Risk Premium
A9: 6 | B9: Perpetuity Growth Rate for Terminal Value
A10: 7 | B10: Basis for selection of peer companies
A11: 8 | B11: Sensitivity Analysis
A12: 9 | B12: Peer Comparison

Sheet Assumption
E1: Forecasted Income Statement
A3: Year | B3: 2016 | C3: 2017 | D3: 2018 | E3: 2019 | F3: 2020 | G3: 2021 | H3: 2022 | I3: 2023 | J3: 2024 | K3: 2025 | L3: 2026 | M3: 2027 | N3: 2028 | O3: 2029 | P3: 2030 | Q3: YOY
A4: INCOME :
A5: Sales Turnover | B5: 5422.57 | C5: 5369.84 | D5: 5609.06 | E5: 6273.19 | F5: 6309.8 | G5: 7184.73 | H5: 8179.5 | I5: 8684.35 | J5: 9135.6 | K5: 9070.71 | L5: =K5*(1+$Q$9) -> 9609.8811 | M5: =L5*(1+$Q$9) -> 10181.101 | N5: =M5*(1+$Q$9) -> 10786.275 | O5: =N5*(1+$Q$9) -> 11427.421 | P5: =O5*(1+$Q$9) -> 12106.677
A6: Stock Adjustments | B6: 23.77 | C6: 8.19 | D6: 74.03 | E6: -10.09 | F6: 69.89 | G6: 176.71 | H6: 28.49 | I6: 24.98 | J6: -49.18 | K6: -12.9
A7: Net Sales | B7: =SUM(B5:B6) -> 5446.34 | C7: =SUM(C5:C6) -> 5378.03 | D7: =SUM(D5:D6) -> 5683.09 | E7: =SUM(E5:E6) -> 6263.1 | F7: =SUM(F5:F6) -> 6379.69 | G7: =SUM(G5:G6) -> 7361.44 | H7: =SUM(H5:H6) -> 8207.99 | I7: =SUM(I5:I6) -> 8709.33 | ... K7: =SUM(K5:K6) -> 9057.81 | L7: =L5+L6 -> 9609.8811 | M7: =M5+M6 -> 10181.101 | N7: =N5+N6 -> 10786.275 | O7: =O5+O6 -> 11427.421 | P7: =P5+P6 -> 12106.677
A8: Total Income | B8: =B7 -> 5446.34 | C8: =C7 -> 5378.03 | D8: =D7 -> 5683.09 | E8: =E7 -> 6263.1 | F8: =F7 -> 6379.69 | G8: =G7 -> 7361.44 | H8: =H7 -> 8207.99 | I8: =I7 -> 8709.33 | ... K8: =K7 -> 9057.81 | L8: =K8*(1+$Q$9) -> 9596.2143 | M8: =L8*(1+$Q$9) -> 10166.622 | N8: =M8*(1+$Q$9) -> 10770.935 | O8: =N8*(1+$Q$9) -> 11411.169 | P8: =O8*(1+$Q$9) -> 12089.459
A9: YOY | C9: =(C8-B8)/B8 -> -0.012542368 | D9: =(D8-C8)/C8 -> 0.056723373 | E9: =(E8-D8)/D8 -> 0.10205892 | F9: =(F8-E8)/E8 -> 0.018615382 | G9: =(G8-F8)/F8 -> 0.15388679 | H9: =(H8-G8)/G8 -> 0.11499788 | I9: =(I8-H8)/H8 -> 0.061079509 | J9: =(J8-I8)/I8 -> 0.043297246 | K9: =(K8-J8)/J8 -> -0.0031486548 | Q9: =AVERAGE(C9:K9) -> 0.059440897 | R9: Average
A10: Raw Materials | B10: 2150.59 | C10: 2129.17 | D10: 2281.22 | E10: 2511.23 | F10: 2531.18 | G10: 3065.28 | H10: 3444.55 | I10: 3797.74 | J10: 3797.27 | K10: 3896.24 | L10: =K10*(1+$Q$16) -> 4154.89 | M10: =L10*(1+$Q$16) -> 4430.7104 | N10: =M10*(1+$Q$16) -> 4724.8409 | O10: =N10*(1+$Q$16) -> 5038.4972 | P10: =O10*(1+$Q$16) -> 5372.9754
A11: Power & Fuel Cost | B11: 47.77 | C11: 50.61 | D11: 59.43 | E11: 63.99 | F11: 66.48 | G11: 70.72 | H11: 85.02 | I11: 93.32 | J11: 99.23 | K11: 97.85 | L11: =K11*(1+$Q$16) -> 104.34572 | M11: =L11*(1+$Q$16) -> 111.27267 | N11: =M11*(1+$Q$16) -> 118.65945 | O11: =N11*(1+$Q$16) -> 126.5366 | P11: =O11*(1+$Q$16) -> 134.93667
A12: Employee Cost | B12: 431.89 | C12: 425.3 | D12: 461.13 | E12: 572.33 | F12: 578.26 | G12: 655.82 | H12: 678.71 | I12: 725.96 | J12: 782.14 | K12: 776.86 | L12: =K12*(1+$Q$16) -> 828.43147 | M12: =L12*(1+$Q$16) -> 883.4265 | N12: =M12*(1+$Q$16) -> 942.07234 | O12: =N12*(1+$Q$16) -> 1004.6114 | P12: =O12*(1+$Q$16) -> 1071.302
A13: Other Manufacturing Expenses | B13: 716.49 | C13: 732.62 | D13: 756.51 | E13: 804.04 | F13: 854.86 | G13: 880.46 | H13: 1049.95 | I13: 1199.1 | J13: 1192.6 | K13: 1165.16 | L13: =K13*(1+$Q$16) -> 1242.5086 | M13: =L13*(1+$Q$16) -> 1324.9919 | N13: =M13*(1+$Q$16) -> 1412.9509 | O13: =N13*(1+$Q$16) -> 1506.7489 | P13: =O13*(1+$Q$16) -> 1606.7737
A14: Selling and Administration Expenses | B14: 733.72 | C14: 748.55 | D14: 776.29 | E14: 835 | F14: 847.58 | G14: 1002.15 | H14: 1068.62 | I14: 1021.29 | J14: 1228.56 | K14: 1267.24 | L14: =K14*(1+$Q$16) -> 1351.3651 | M14: =L14*(1+$Q$16) -> 1441.0748 | N14: =M14*(1+$Q$16) -> 1536.7399 | O14: =N14*(1+$Q$16) -> 1638.7556 | P14: =O14*(1+$Q$16) -> 1747.5436
A15: Total Expenditure | B15: =SUM(B10:B14) -> 4080.46 | C15: =SUM(C10:C14) -> 4086.25 | D15: =SUM(D10:D14) -> 4334.58 | E15: =SUM(E10:E14) -> 4786.59 | F15: =SUM(F10:F14) -> 4878.36 | G15: =SUM(G10:G14) -> 5674.43 | H15: =SUM(H10:H14) -> 6326.85 | I15: =SUM(I10:I14) -> 6837.41 | ... K15: =SUM(K10:K14) -> 7203.35 | L15: =K15*(1+$Q$16) -> 7681.5409 | M15: =L15*(1+$Q$16) -> 8191.4763 | N15: =M15*(1+$Q$16) -> 8735.2635 | O15: =N15*(1+$Q$16) -> 9315.1497 | P15: =O15*(1+$Q$16) -> 9933.5314
A16: YOY | C16: =(C15-B15)/B15 -> 0.0014189577 | D16: =(D15-C15)/C15 -> 0.060772102 | E16: =(E15-D15)/D15 -> 0.10428 | F16: =(F15-E15)/E15 -> 0.019172313 | G16: =(G15-F15)/F15 -> 0.16318394 | H16: =(H15-G15)/G15 -> 0.11497542 | I16: =(I15-H15)/H15 -> 0.080697345 | J16: =(J15-I15)/I15 -> 0.038375642 | K16: =(K15-J15)/J15 -> 0.014584918 | Q16: =AVERAGE(C16:K16) -> 0.066384516 | R16: Average
A17: Operating Profit | B17: =B8-B15 -> 1365.88 | C17: =C8-C15 -> 1291.78 | D17: =D8-D15 -> 1348.51 | E17: =E8-E15 -> 1476.51 | F17: =F8-F15 -> 1501.33 | G17: =G8-G15 -> 1687.01 | H17: =H8-H15 -> 1881.14 | I17: =I8-I15 -> 1871.92 | ... K17: =K8-K15 -> 1854.46 | L17: =K17*(1+$Q$18) -> 1922.4554 | M17: =L17*(1+$Q$18) -> 1992.9439 | N17: =M17*(1+$Q$18) -> 2066.017 | O17: =N17*(1+$Q$18) -> 2141.7693 | P17: =O17*(1+$Q$18) -> 2220.2992
A18: YOY | C18: =(C17-B17)/B17 -> -0.054250739 | D18: =(D17-C17)/C17 -> 0.043916147 | E18: =(E17-D17)/D17 -> 0.094919578 | F18: =(F17-E17)/E17 -> 0.01680991 | G18: =(G17-F17)/F17 -> 0.12367701 | H18: =(H17-G17)/G17 -> 0.11507341 | I18: =(I17-H17)/H17 -> -0.0049012833 | J18: =(J17-I17)/I17 -> 0.061273986 | K18: =(K17-J17)/J17 -> -0.066525053 | Q18: =AVERAGE(C18:K18) -> 0.036665885 | AC18: ..0320
A19: Interest | B19: 10.26 | C19: 16.23 | D19: 21.89 | E19: 29.8 | F19: 19.27 | G19: 9.14 | H19: 18.67 | I19: 46.37 | J19: 81.14 | K19: 99.58 | L19: =K19*(1+$Q$20) -> 142.91224 | M19: =L19*(1+$Q$20) -> 205.1005 | N19: =M19*(1+$Q$20) -> 294.34999 | O19: =N19*(1+$Q$20) -> 422.43639 | P19: =O19*(1+$Q$20) -> 606.2596
A20: YOY | C20: =(C19-B19)/B19 -> 0.58187135 | D20: =(D19-C19)/C19 -> 0.34873691 | E20: =(E19-D19)/D19 -> 0.36135222 | F20: =(F19-E19)/E19 -> -0.3533557 | G20: =(G19-F19)/F19 -> -0.5256876 | H20: =(H19-G19)/G19 -> 1.0426696 | I20: =(I19-H19)/H19 -> 1.4836636 | J20: =(J19-I19)/I19 -> 0.74983826 | K20: =(K19-J19)/J19 -> 0.22726152 | Q20: =AVERAGE(C20:K20) -> 0.43515002
A21: Gross Profit | B21: 1282.18 | C21: 1369.78 | D21: 1475.63 | E21: 1612.18 | F21: 1538.4 | G21: 1826.71 | H21: 2056.7 | I21: 2016.96 | J21: 2175.56 | K21: 2059.27 | L21: =K21*(1+$Q$22) -> 2176.3143 | M21: =L21*(1+$Q$22) -> 2300.0112 | N21: =M21*(1+$Q$22) -> 2430.7387 | O21: =N21*(1+$Q$22) -> 2568.8965 | P21: =O21*(1+$Q$22) -> 2714.9068
A22: YOY | C22: =(C21-B21)/B21 -> 0.068321141 | D22: =(D21-C21)/C21 -> 0.077275183 | E22: =(E21-D21)/D21 -> 0.092536747 | F22: =(F21-E21)/E21 -> -0.045764121 | G22: =(G21-F21)/F21 -> 0.187409 | H22: =(H21-G21)/G21 -> 0.12590395 | I22: =(I21-H21)/H21 -> -0.019322215 | J22: =(J21-I21)/I21 -> 0.078633191 | K22: =(K21-J21)/J21 -> -0.053452904 | Q22: =AVERAGE(C22:K22) -> 0.056837774
A23: Depreciation | B23: 72.83 | C23: 75.43 | D23: 102.5 | E23: 108.83 | F23: 129.93 | G23: 143.4 | H23: 160.39 | I23: 188.29 | J23: 208.86 | K23: 250.93 | L23: =K23*(1+$Q$24) -> 288.7643 | M23: =L23*(1+$Q$24) -> 332.30313 | N23: =M23*(1+$Q$24) -> 382.40657 | O23: =N23*(1+$Q$24) -> 440.06443 | P23: =O23*(1+$Q$24) -> 506.41573
A24: YOY | C24: =(C23-B23)/B23 -> 0.035699574 | D24: =(D23-C23)/C23 -> 0.35887578 | E24: =(E23-D23)/D23 -> 0.061756098 | F24: =(F23-E23)/E23 -> 0.19388036 | G24: =(G23-F23)/F23 -> 0.10367121 | H24: =(H23-G23)/G23 -> 0.11847978 | I24: =(I23-H23)/H23 -> 0.17395099 | J24: =(J23-I23)/I23 -> 0.10924638 | K24: =(K23-J23)/J23 -> 0.20142679 | Q24: =AVERAGE(C24:K24) -> 0.15077633
A25: Profit Before Tax | B25: 1209.35 | C25: 1294.35 | D25: 1373.13 | E25: 1503.35 | F25: 1408.47 | G25: 1683.31 | H25: 1896.31 | I25: 1828.67 | J25: 1966.7 | K25: 1808.34 | L25: =L21-L23 -> 1887.55 | M25: =M21-M23 -> 1967.7081 | N25: =N21-N23 -> 2048.3321 | O25: =O21-O23 -> 2128.832 | P25: =P21-P23 -> 2208.4911
A26: Tax | B26: 259.11 | C26: 310.83 | D26: 340.33 | E26: 369.28 | F26: 425.4 | G26: 299.75 | H26: 378.97 | I26: 423.86 | J26: 443.8 | K26: 393.12 | L26: =L25*(1+$Q$27) -> 2322.1906 | M26: =M25*(1+$Q$27) -> 2420.8064 | N26: =N25*(1+$Q$27) -> 2519.9956 | O26: =O25*(1+$Q$27) -> 2619.032 | P26: =P25*(1+$Q$27) -> 2717.0339
A27: Tax rate | B27: =B26/B25 -> 0.21425559 | C27: =C26/C25 -> 0.2401437 | D27: =D26/D25 -> 0.2478498 | E27: =E26/E25 -> 0.24563807 | F27: =F26/F25 -> 0.30202986 | G27: =G26/G25 -> 0.17807178 | H27: =H26/H25 -> 0.19984602 | I27: =I26/I25 -> 0.23178594 | ... K27: =K26/K25 -> 0.21739275 | Q27: =AVERAGE(B27:K27) -> 0.23026707
A28: Deferred Tax | B28: 12.98 | C28: -14.81 | D28: -39.25 | E28: -130.22 | F28: -187.28 | G28: 1.67 | H28: 84.41 | I28: 31.55 | J28: 13.69 | K28: 12 | L28: =K28*(1+$Q$29) -> 77.980492 | M28: =L28*(1+$Q$29) -> 506.74643 | N28: =M28*(1+$Q$29) -> 3293.028 | O28: =N28*(1+$Q$29) -> 21399.329 | P28: =O28*(1+$Q$29) -> 139060.85
A29: YOY | C29: =(C28-B28)/B28 -> -2.1409861 | D29: =(D28-C28)/C28 -> 1.6502363 | E29: =(E28-D28)/D28 -> 2.317707 | F29: =(F28-E28)/E28 -> 0.43818154 | G29: =(G28-F28)/F28 -> -1.0089171 | H29: =(H28-G28)/G28 -> 49.54491 | I29: =(I28-H28)/H28 -> -0.62622912 | J29: =(J28-I28)/I28 -> -0.56608558 | K29: =(K28-J28)/J28 -> -0.12344777 | Q29: =AVERAGE(C29:K29) -> 5.4983744
A30: Reported Net Profit | B30: =B25-B26 -> 950.24 | C30: =C25-C26 -> 983.52 | D30: =D25-D26 -> 1032.8 | E30: =E25-E26 -> 1134.07 | F30: =F25-F26 -> 983.07 | G30: =G25-G26 -> 1383.56 | H30: =H25-H26 -> 1517.34 | I30: =I25-I26 -> 1404.81 | ... K30: =K25-K26 -> 1415.22 | L30: =L25+L26+L28 -> 4287.7211 | M30: =M25+M26+M28 -> 4895.2609 | N30: =N25+N26+N28 -> 7861.3557 | O30: =O25+O26+O28 -> 26147.193 | P30: =P25+P26+P28 -> 143986.38
A31: Extraordinary Items | B31: 20.3 | C31: -0.65 | D31: -9.12 | E31: 0.67 | F31: -69.72 | G31: 0.62 | H31: -0.51 | I31: -9.85 | J31: -1.03 | K31: -0.99 | L31: =K31*(1+$Q$32) -> 7.7645074 | M31: =L31*(1+$Q$32) -> -60.896541 | N31: =M31*(1+$Q$32) -> 477.60772 | O31: =N31*(1+$Q$32) -> -3745.8472 | P31: =O31*(1+$Q$32) -> 29378.443
A32: YOY | C32: =(C31-B31)/B31 -> -1.0320197 | D32: =(D31-C31)/C31 -> 13.030769 | E32: =(E31-D31)/D31 -> -1.0734649 | F32: =(F31-E31)/E31 -> -105.0597 | G32: =(G31-F31)/F31 -> -1.0088927 | H32: =(H31-G31)/G31 -> -1.8225806 | I32: =(I31-H31)/H31 -> 18.313725 | J32: =(J31-I31)/I31 -> -0.89543147 | K32: =(K31-J31)/J31 -> -0.038834951 | Q32: =AVERAGE(C32:K32) -> -8.8429368
A33: Adjusted Net Profit | B33: 916.96 | C33: 998.98 | D33: 1081.17 | E33: 1263.62 | F33: 1240.07 | G33: 1381.27 | H33: 1433.44 | I33: 1383.11 | J33: 1510.24 | K33: 1404.21 | L33: =L30-L31 -> 4279.9566 | M33: =M30-M31 -> 4956.1575 | N33: =N30-N31 -> 7383.748 | O33: =O30-O31 -> 29893.04 | P33: =P30-P31 -> 114607.93
A34: Dividend | B34: 423.2 | C34: 220.19 | D34: 220.19 | E34: 220.79 | F34: 247.39 | G34: 309.3 | H34: 0 | I34: 0 | J34: 0 | K34: 0
A35: YOY | C35: =(C34-B34)/B34 -> -0.47970227 | D35: =(D34-C34)/C34 -> 0 | E35: =(E34-D34)/D34 -> 0.0027249194 | F35: =(F34-E34)/E34 -> 0.12047647 | G35: =(G34-F34)/F34 -> 0.25025264 | H35: =(H34-G34)/G34 -> -1 | I35: =(I34-H34)/H34 -> #DIV/0! | J35: =(J34-I34)/I34 -> #DIV/0! | K35: =(K34-J34)/J34 -> #DIV/0!
A36: RE | B36: =B33-B34 -> 493.76 | C36: =C33-C34 -> 778.79 | D36: =D33-D34 -> 860.98 | E36: =E33-E34 -> 1042.83 | F36: =F33-F34 -> 992.68 | G36: =G33-G34 -> 1071.97 | H36: =H33-H34 -> 1433.44 | I36: =I33-I34 -> 1383.11 | ... K36: =K33-K34 -> 1404.21
A40: Adjust profit | B40: NI + Current Year R&D exp- amortization of r and D
A41: Balance Sheet
A43: Year | B43: 2016 | C43: 2017 | D43: 2018 | E43: 2019 | F43: 2020 | G43: 2021 | H43: 2022 | I43: 2023 | J43: 2024 | K43: 2025 | L43: 2026 | M43: 2027 | N43: 2028 | O43: 2029 | P43: 2030
A44: SOURCES OF FUNDS : | O44: 2029 | P44: 2030
A45: Share Capital | B45: =Bal.sheet!B4 -> 175.91 | C45: =Bal.sheet!C4 -> 176.15 | D45: =Bal.sheet!D4 -> 176.15 | E45: =Bal.sheet!E4 -> 176.63 | F45: =Bal.sheet!F4 -> 176.71 | G45: =Bal.sheet!G4 -> 176.74 | H45: =Bal.sheet!H4 -> 176.79 | I45: =Bal.sheet!I4 -> 177.18 | ... K45: =Bal.sheet!K4 -> 177.23 | L45: 177.2 | M45: 177.2 | N45: 177.2 | O45: 177.2 | P45: 177.2
...

Sheet financial satement
A1: FINANCIAL STATEMENTS OF TATA STEEL LTD | B1: ACTUAL PERIOD | G1: FORECASTED PERIOD
A2: Number of Days | B2: 365 | C2: 365 | D2: 365 | E2: 365 | F2: 365 | G2: 365 | H2: 365 | I2: 365 | J2: 365 | K2: 365
A4: Profit and Loss Statement
A5: Particulars | B5: 2016 | C5: 2017 | D5: 2018 | E5: 2019 | F5: 2020 | G5: 2021 | H5: 2022 | I5: 2023 | J5: 2024 | K5: 2025 | L5: 2026 | M5: 2027 | N5: 2028 | O5: 2029 | P5: 2030
A7: Revenue from Operations | B7: =PL!K4 -> 5422.57 | C7: =PL!J4 -> 5369.84 | D7: =PL!I4 -> 5609.06 | E7: =PL!H4 -> 6273.19 | F7: =PL!G4 -> 6309.8 | G7: =PL!F4 -> 7184.73 | H7: =PL!E4 -> 8179.5 | I7: =PL!D4 -> 8684.35 | J7: =PL!C4 -> 9135.6 | K7: =PL!B4 -> 9070.71 | L7: =Assumption!L5 -> 9609.8811 | M7: =Assumption!M5 -> 10181.101 | N7: =Assumption!N5 -> 10786.275 | O7: =Assumption!O5 -> 11427.421 | P7: =Assumption!P5 -> 12106.677
A8: Other revenues | B8: =PL!K6 -> 194.36 | C8: =PL!J6 -> 274.64 | D8: =PL!I6 -> 283.23 | E8: =PL!H6 -> 274.74 | F8: =PL!G6 -> 276.9 | G8: =PL!F6 -> 276.65 | H8: =PL!E6 -> 341.55 | I8: =PL!D6 -> 392.17 | J8: =PL!C6 -> 417.62 | K8: =PL!B6 -> 451.94
A9: Revenue | B9: =PL!K8 -> 5558.17 | C9: =PL!J8 -> 5573.48 | D9: =PL!I8 -> 5949.55 | E9: =PL!H8 -> 6537.84 | F9: =PL!G8 -> 6656.59 | G9: =PL!F8 -> 7638.09 | H9: =PL!E8 -> 8549.54 | I9: =PL!D8 -> 9101.5 | J9: =PL!C8 -> 9504.04 | K9: =PL!B8 -> 9509.75 | L9: =Assumption!L8 -> 9596.2143 | M9: =Assumption!M8 -> 10166.622 | N9: =Assumption!N8 -> 10770.935 | O9: =Assumption!O8 -> 11411.169 | P9: =Assumption!P8 -> 12089.459
A11: Cost of Material Consumed | B11: =PL!K10 -> 2150.59 | C11: =PL!J10 -> 2129.17 | D11: =PL!I10 -> 2281.22 | E11: =PL!H10 -> 2511.23 | F11: =PL!G10 -> 2531.18 | G11: =PL!F10 -> 3065.28 | H11: =PL!E10 -> 3444.55 | I11: =PL!D10 -> 3797.74 | J11: =PL!C10 -> 3797.27 | K11: =PL!B10 -> 3896.24 | L11: =Assumption!L10 -> 4154.89 | M11: =Assumption!M10 -> 4430.7104 | N11: =Assumption!N10 -> 4724.8409 | O11: =Assumption!O10 -> 5038.4972 | P11: =Assumption!P10 -> 5372.9754
A12: Purchase Of Stock-In Trade | B12: =PL!K7 -> 23.77 | C12: =PL!J7 -> 8.19 | D12: =PL!I7 -> 74.03 | E12: =PL!H7 -> -10.09 | F12: =PL!G7 -> 69.89 | G12: =PL!F7 -> 176.71 | H12: =PL!E7 -> 28.49 | I12: =PL!D7 -> 24.98 | J12: =PL!C7 -> -49.18 | K12: =PL!B7 -> -12.9
A13: Changes In Inventories Of FG,WIP And Stock-In Trade | B13: =PL!K11 -> 47.77 | C13: =PL!J11 -> 50.61 | D13: =PL!I11 -> 59.43 | E13: =PL!H11 -> 63.99 | F13: =PL!G11 -> 66.48 | G13: =PL!F11 -> 70.72 | H13: =PL!E11 -> 85.02 | I13: =PL!D11 -> 93.32 | J13: =PL!C11 -> 99.23 | K13: =PL!B11 -> 97.85 | L13: =Assumption!L11 -> 104.34572 | M13: =Assumption!M11 -> 111.27267 | N13: =Assumption!N11 -> 118.65945 | O13: =Assumption!O11 -> 126.5366 | P13: =Assumption!P11 -> 134.93667
A14: Cost of Goods sold | B14: =B11+B12+B13 -> 2222.13 | C14: =C11+C12+C13 -> 2187.97 | D14: =D11+D12+D13 -> 2414.68 | E14: =E11+E12+E13 -> 2565.13 | F14: =F11+F12+F13 -> 2667.55 | G14: =G11+G12+G13 -> 3312.71 | H14: =H11+H12+H13 -> 3558.06 | I14: =I11+I12+I13 -> 3916.04 | ... P14: =P11+P12+P13 -> 5507.9121
A15: Gross Margin | B15: =B9-B14 -> 3336.04 | C15: =C9-C14 -> 3385.51 | D15: =D9-D14 -> 3534.87 | E15: =E9-E14 -> 3972.71 | F15: =F9-F14 -> 3989.04 | G15: =G9-G14 -> 4325.38 | H15: =H9-H14 -> 4991.48 | I15: =I9-I14 -> 5185.46 | ... P15: =P9-P14 -> 6581.5472
A17: Employee Benefit Expenses | B17: =PL!K12 -> 431.89 | C17: =PL!J12 -> 425.3 | D17: =PL!I12 -> 461.13 | E17: =PL!H12 -> 572.33 | F17: =PL!G12 -> 578.26 | G17: =PL!F12 -> 655.82 | H17: =PL!E12 -> 678.71 | I17: =PL!D12 -> 725.96 | J17: =PL!C12 -> 782.14 | K17: =PL!B12 -> 776.86 | L17: =Assumption!L12 -> 828.43147 | M17: =Assumption!M12 -> 883.4265 | N17: =Assumption!N12 -> 942.07234 | O17: =Assumption!O12 -> 1004.6114 | P17: =Assumption!P12 -> 1071.302
A18: Other Expenses | B18: =PL!K13+PL!K14+PL!K15 -> 1635.48 | C18: =PL!J13+PL!J14+PL!J15 -> 1582.39 | D18: =PL!I13+PL!I14+PL!I15 -> 1650.25 | E18: =PL!H13+PL!H14+PL!H15 -> 1748.31 | F18: =PL!G13+PL!G14+PL!G15 -> 1923 | G18: =PL!F13+PL!F14+PL!F15 -> 2010.42 | H18: =PL!E13+PL!E14+PL!E15 -> 2265.89 | I18: =PL!D13+PL!D14+PL!D15 -> 2421.15 | J18: =PL!C13+PL!C14+PL!C15 -> 2568.7 | K18: =PL!B13+PL!B14+PL!B15 -> 2579.95 | L18: =Assumption!L13+Assumption!L14 -> 2593.8737 | M18: =Assumption!M13+Assumption!M14 -> 2766.0667 | N18: =Assumption!N13+Assumption!N14 -> 2949.6907 | O18: =Assumption!O13+Assumption!O14 -> 3145.5045 | P18: =Assumption!P13+Assumption!P14 -> 3354.3173
A19: EBITDA | B19: =B15-B17-B18 -> 1268.67 | C19: =C15-C17-C18 -> 1377.82 | D19: =D15-D17-D18 -> 1423.49 | E19: =E15-E17-E18 -> 1652.07 | F19: =F15-F17-F18 -> 1487.78 | G19: =G15-G17-G18 -> 1659.14 | H19: =H15-H17-H18 -> 2046.88 | I19: =I15-I17-I18 -> 2038.35 | ... P19: =P15-P17-P18 -> 2155.9278
A21: Depreciation And Amortisation Expenses | B21: =PL!K21 -> 72.83 | C21: =PL!J21 -> 75.43 | D21: =PL!I21 -> 102.5 | E21: =PL!H21 -> 108.83 | F21: =PL!G21 -> 129.93 | G21: =PL!F21 -> 143.4 | H21: =PL!E21 -> 160.39 | I21: =PL!D21 -> 188.29 | J21: =PL!C21 -> 208.86 | K21: =PL!B21 -> 250.93 | L21: =Assumption!L23 -> 288.7643 | M21: =Assumption!M23 -> 332.30313 | N21: =Assumption!N23 -> 382.40657 | O21: =Assumption!O23 -> 440.06443 | P21: =Assumption!P23 -> 506.41573
A22: EBIT | B22: =B19-B21 -> 1195.84 | C22: =C19-C21 -> 1302.39 | D22: =D19-D21 -> 1320.99 | E22: =E19-E21 -> 1543.24 | F22: =F19-F21 -> 1357.85 | G22: =G19-G21 -> 1515.74 | H22: =H19-H21 -> 1886.49 | I22: =I19-I21 -> 1850.06 | ... P22: =P19-P21 -> 1649.5121
A24: Finance Cost | B24: =PL!K19 -> 10.26 | C24: =PL!J19 -> 16.23 | D24: =PL!I19 -> 21.89 | E24: =PL!H19 -> 29.8 | F24: =PL!G19 -> 19.27 | G24: =PL!F19 -> 9.14 | H24: =PL!E19 -> 18.67 | I24: =PL!D19 -> 46.37 | J24: =PL!C19 -> 81.14 | K24: =PL!B19 -> 99.58 | L24: =Assumption!L19 -> 142.91224 | M24: =Assumption!M19 -> 205.1005 | N24: =Assumption!N19 -> 294.34999 | O24: =Assumption!O19 -> 422.43639 | P24: =Assumption!P19 -> 606.2596
A25: EBT | B25: =B22-B24 -> 1185.58 | C25: =C22-C24 -> 1286.16 | D25: =D22-D24 -> 1299.1 | E25: =E22-E24 -> 1513.44 | F25: =F22-F24 -> 1338.58 | G25: =G22-G24 -> 1506.6 | H25: =H22-H24 -> 1867.82 | I25: =I22-I24 -> 1803.69 | ... P25: =P22-P24 -> 1043.2525
A26: Tax Rate | B26: =Assumption!B27 -> 0.21425559 | C26: =Assumption!C27 -> 0.2401437 | D26: =Assumption!D27 -> 0.2478498 | E26: =Assumption!E27 -> 0.24563807 | F26: =Assumption!F27 -> 0.30202986 | G26: =Assumption!G27 -> 0.17807178 | H26: =Assumption!H27 -> 0.19984602 | I26: =Assumption!I27 -> 0.23178594 | ... P26: =Assumption!P27 -> 0
A27: Current Tax | B27: =PL!K23 -> 259.11 | C27: =PL!J23 -> 310.83 | D27: =PL!I23 -> 340.33 | E27: =PL!H23 -> 369.28 | F27: =PL!G23 -> 425.4 | G27: =PL!F23 -> 299.75 | H27: =PL!E23 -> 378.97 | I27: =PL!D23 -> 423.86 | J27: =PL!C23 -> 443.8 | K27: =PL!B23 -> 393.12 | L27: =L25*L26 -> 0 | M27: =M25*M26 -> 0 | N27: =N25*N26 -> 0 | O27: =O25*O26 -> 0 | P27: =P25*P26 -> 0
A28: Deferred Tax | B28: =PL!K25 -> 12.98 | C28: =PL!J25 -> -14.81 | D28: =PL!I25 -> -39.25 | E28: =PL!H25 -> -130.22 | F28: =PL!G25 -> -187.28 | G28: =PL!F25 -> 1.67 | H28: =PL!E25 -> 84.41 | I28: =PL!D25 -> 31.55 | J28: =PL!C25 -> 13.69 | K28: =PL!B25 -> 12 | L28: =Assumption!L28 -> 77.980492 | M28: =Assumption!M28 -> 506.74643 | N28: =Assumption!N28 -> 3293.028 | O28: =Assumption!O28 -> 21399.329 | P28: =Assumption!P28 -> 139060.85
A29: Net Income | B29: =B25-B27-B28 -> 913.49 | C29: =C25-C27-C28 -> 990.14 | D29: =D25-D27-D28 -> 998.02 | E29: =E25-E27-E28 -> 1274.38 | F29: =F25-F27-F28 -> 1100.46 | G29: =G25-G27-G28 -> 1205.18 | H29: =H25-H27-H28 -> 1404.44 | I29: =I25-I27-I28 -> 1348.28 | ... P29: =P25-P27-P28 -> -138017.6
A30: EPS | B30: =PL!K38 -> 5.33 | C30: =PL!J38 -> 5.67 | D30: =PL!I38 -> 6.09 | E30: =PL!H38 -> 7.16 | F30: =PL!G38 -> 6.62 | G30: =PL!F38 -> 7.82 | H30: =PL!E38 -> 8.11 | I30: =PL!D38 -> 7.75 | J30: =PL!C38 -> 8.52 | K30: =PL!B38 -> 7.92
A31: Dividend | B31: =PL!K34 -> 423.2 | C31: =PL!J34 -> 220.19 | D31: =PL!I34 -> 220.19 | E31: =PL!H34 -> 220.79 | F31: =PL!G34 -> 247.39 | G31: =PL!F34 -> 309.3 | H31: =PL!E34 -> 0 | I31: =PL!D34 -> 0 | J31: =PL!C34 -> 0 | K31: =PL!B34 -> 0 | L31: =Assumption!L34 -> 0 | M31: =Assumption!M34 -> 0 | N31: =Assumption!N34 -> 0 | O31: =Assumption!O34 -> 0 | P31: =Assumption!P34 -> 0
A32: Rate of Dividend | B32: =PL!K36 -> 225 | C32: =PL!J36 -> 225 | D32: =PL!I36 -> 750 | E32: =PL!H36 -> 275 | F32: =PL!G36 -> 300 | G32: =PL!F36 -> 475 | H32: =PL!E36 -> 520 | I32: =PL!D36 -> 520 | J32: =PL!C36 -> 550 | K32: =PL!B36 -> 800
A35: Balance Sheet
A37: INR in Cr. | B37: 2016 | C37: 2017 | D37: 2018 | E37: 2019 | F37: 2020 | G37: 2021 | H37: 2022 | I37: 2023 | J37: 2024 | K37: 2025 | L37: 2026 | M37: 2027 | N37: 2028 | O37: 2029 | P37: 2030
A38: Share Capital | B38: =Bal.sheet!B4 -> 175.91 | C38: =Bal.sheet!C4 -> 176.15 | D38: =Bal.sheet!D4 -> 176.15 | E38: =Bal.sheet!E4 -> 176.63 | F38: =Bal.sheet!F4 -> 176.71 | G38: =Bal.sheet!G4 -> 176.74 | H38: =Bal.sheet!H4 -> 176.79 | I38: =Bal.sheet!I4 -> 177.18 | ... K38: =Bal.sheet!K4 -> 177.23 | L38: =Assumption!L45 -> 177.2 | M38: =Assumption!M45 -> 177.2 | N38: =Assumption!N45 -> 177.2 | O38: =Assumption!O45 -> 177.2 | P38: =Assumption!P45 -> 177.2
A39: Reserves | B39: =Bal.sheet!B5 -> 2918.38 | C39: =Bal.sheet!C5 -> 3481.73 | D39: =Bal.sheet!D5 -> 4050.71 | E39: =Bal.sheet!E5 -> 3792.19 | F39: =Bal.sheet!F5 -> 4397.52 | G39: =Bal.sheet!G5 -> 5214.48 | H39: =Bal.sheet!H5 -> 5687.08 | I39: =Bal.sheet!I5 -> 6109.7 | ... K39: =Bal.sheet!K5 -> 7246.06 | L39: =Assumption!L46 -> 17170774 | M39: =Assumption!M46 -> 4.0689077e+10 | N39: =Assumption!N46 -> 9.6419705e+13 | O39: =Assumption!O46 -> 2.2848293e+17 | P39: =Assumption!P46 -> 5.4142925e+20
A40: Employee Stock Options
A41: Total Equity | B41: =Bal.sheet!B8 -> 3094.29 | C41: =Bal.sheet!C8 -> 3657.88 | D41: =Bal.sheet!D8 -> 4226.86 | E41: =Bal.sheet!E8 -> 3968.82 | F41: =Bal.sheet!F8 -> 4574.23 | G41: =Bal.sheet!G8 -> 5391.22 | H41: =Bal.sheet!H8 -> 5863.87 | I41: =Bal.sheet!I8 -> 6286.88 | ... K41: =Bal.sheet!K8 -> 7423.29 | L41: =Assumption!L47 -> 17170952 | M41: =Assumption!M47 -> 4.0689078e+10 | N41: =Assumption!N47 -> 9.6419705e+13 | O41: =Assumption!O47 -> 2.2848293e+17 | P41: =Assumption!P47 -> 5.4142925e+20
A43: Long Term Borrowings | B43: =Bal.sheet!B10 -> 79.55 | C43: =Bal.sheet!C10 -> 74.68 | D43: =Bal.sheet!D10 -> 78.01 | E43: =Bal.sheet!E10 -> 82.13 | F43: =Bal.sheet!F10 -> 49.46 | G43: =Bal.sheet!G10 -> 152.93 | H43: =Bal.sheet!H10 -> 560.18 | I43: =Bal.sheet!I10 -> 437.7 | ... K43: =Bal.sheet!K10 -> 378.62 | L43: =Assumption!L48 -> 546.31212 | M43: =Assumption!M48 -> 788.27565 | N43: =Assumption!N48 -> 1137.4057 | O43: =Assumption!O48 -> 1641.1666 | P43: =Assumption!P48 -> 2368.045
A44: Deferred Tax Liabilities [Net] | B44: =Bal.sheet!B37 -> 89.74 | C44: =Bal.sheet!C37 -> 104.07 | D44: =Bal.sheet!D37 -> 113.83 | E44: =Bal.sheet!E37 -> 110.93 | F44: =Bal.sheet!F37 -> 129.67 | G44: =Bal.sheet!G37 -> 131.5 | H44: =Bal.sheet!H37 -> 148.36 | I44: =Bal.sheet!I37 -> 177 | ... K44: =Bal.sheet!K37 -> 222.93 | L44: =Assumption!L75 -> 246.77612 | M44: =Assumption!M75 -> 273.17299 | N44: =Assumption!N75 -> 302.39345 | O44: =Assumption!O75 -> 334.73954 | P44: =Assumption!P75 -> 370.54558
A45: Other Non-current Liabilities | B45: =Bal.sheet!B12 -> 49.99 | C45: =Bal.sheet!C12 -> 51.23 | D45: =Bal.sheet!D12 -> 54.29 | E45: =Bal.sheet!E12 -> 57.32 | F45: =Bal.sheet!F12 -> 59.35 | G45: =Bal.sheet!G12 -> 56.92 | H45: =Bal.sheet!H12 -> 60.82 | I45: =Bal.sheet!I12 -> 62.62 | ... K45: =Bal.sheet!K12 -> 64.49
A46: Long Term Provisions | B46: =Bal.sheet!B32 -> 50.85 | C46: =Bal.sheet!C32 -> 64.51 | D46: =Bal.sheet!D32 -> 68.29 | E46: =Bal.sheet!E32 -> 88.92 | F46: =Bal.sheet!F32 -> 127.5 | G46: =Bal.sheet!G32 -> 161.06 | H46: =Bal.sheet!H32 -> 192.93 | I46: =Bal.sheet!I32 -> 202.51 | ... K46: =Bal.sheet!K32 -> 342.69 | L46: =Assumption!L70 -> 384.26086 | M46: =Assumption!M70 -> 430.87458 | N46: =Assumption!N70 -> 483.14289 | O46: =Assumption!O70 -> 541.75173 | P46: =Assumption!P70 -> 607.47027
A47: Total Non-Current Liabilities | B47: =Bal.sheet!B11+Bal.sheet!B12 -> 137.22 | C47: =Bal.sheet!C11+Bal.sheet!C12 -> 334.98 | D47: =Bal.sheet!D11+Bal.sheet!D12 -> 340.9 | E47: =Bal.sheet!E11+Bal.sheet!E12 -> 367.18 | F47: =Bal.sheet!F11+Bal.sheet!F12 -> 210 | G47: =Bal.sheet!G11+Bal.sheet!G12 -> 236.79 | H47: =Bal.sheet!H11+Bal.sheet!H12 -> 621 | I47: =Bal.sheet!I11+Bal.sheet!I12 -> 678.08 | ... K47: =Bal.sheet!K11+Bal.sheet!K12 -> 443.21
A49: Short Term Borrowings | B49: =Bal.sheet!B9 -> 7.68 | C49: =Bal.sheet!C9 -> 209.07 | D49: =Bal.sheet!D9 -> 208.6 | E49: =Bal.sheet!E9 -> 227.73 | F49: =Bal.sheet!F9 -> 101.19 | G49: =Bal.sheet!G9 -> 26.94 | H49: =Bal.sheet!H9 -> 0 | I49: =Bal.sheet!I9 -> 177.76 | ... K49: =Bal.sheet!K9 -> 0.1
A50: Trade payable | B50: =Bal.sheet!B31 -> 1070.85 | C50: =Bal.sheet!C31 -> 1061.37 | D50: =Bal.sheet!D31 -> 1080.62 | E50: =Bal.sheet!E31 -> 1145.54 | F50: =Bal.sheet!F31 -> 1188.38 | G50: =Bal.sheet!G31 -> 1715.09 | H50: =Bal.sheet!H31 -> 1844.16 | I50: =Bal.sheet!I31 -> 2108.21 | ... K50: =Bal.sheet!K31 -> 2663.03 | L50: =Assumption!L69 -> 2986.0755 | M50: =Assumption!M69 -> 3348.3087 | N50: =Assumption!N69 -> 3754.4836 | O50: =Assumption!O69 -> 4209.9306 | P50: =Assumption!P69 -> 4720.6266
A51: Other short term financial liabilities | B51: =Bal.sheet!B28 -> 68.26 | C51: =Bal.sheet!C28 -> 91.81 | D51: =Bal.sheet!D28 -> 132.3 | E51: =Bal.sheet!E28 -> 109.88 | F51: =Bal.sheet!F28 -> 168.15 | G51: =Bal.sheet!G28 -> 148.71 | H51: =Bal.sheet!H28 -> 126.06 | I51: =Bal.sheet!I28 -> 140.4 | ... K51: =Bal.sheet!K28 -> 280.07 | L51: =Assumption!L65 -> 305.46354 | M51: =Assumption!M65 -> 333.15947 | N51: =Assumption!N65 -> 363.36656 | O51: =Assumption!O65 -> 396.31247 | P51: =Assumption!P65 -> 432.24555
...

Sheet PPE Schedule
A1: PPE SCHEDULE | B1: ACTUAL PERIOD | L1: FORECASTED PERIOD
A3: INR in Cr. | B3: 2016 | C3: 2017 | D3: 2018 | E3: 2019 | F3: 2020 | G3: 2021 | H3: 2022 | I3: 2023 | J3: 2024 | K3: 2025 | L3: 2026 | M3: 2027 | N3: 2028 | O3: 2029 | P3: 2030
A4: Revenues | B4: =Assumption!B5 -> 5422.57 | C4: =Assumption!C5 -> 5369.84 | D4: =Assumption!D5 -> 5609.06 | E4: =Assumption!E5 -> 6273.19 | F4: =Assumption!F5 -> 6309.8 | G4: =Assumption!G5 -> 7184.73 | H4: =Assumption!H5 -> 8179.5 | I4: =Assumption!I5 -> 8684.35 | ... P4: =Assumption!P5 -> 12106.677
A5: Opening PP&E | C5: =Bal.sheet!B18 -> 638.81 | D5: =Bal.sheet!C18 -> 993.33 | E5: =Bal.sheet!D18 -> 1030.48 | F5: =Bal.sheet!E18 -> 1036.62 | G5: =Bal.sheet!F18 -> 1134.28 | H5: =Bal.sheet!G18 -> 1204.81 | I5: =Bal.sheet!H18 -> 1399 | J5: =Bal.sheet!I18 -> 1661.97 | K5: =Bal.sheet!J18 -> 1878.2 | L5: =K10 -> 2035.62 | M5: =L10 -> 2116.7794 | N5: =M10 -> 2176.3886 | O5: =N10 -> 2209.1899 | P5: =O10 -> 2209.0137
A6: Capex | B6: =-cashflow!K31 -> 106.84 | C6: =-cashflow!J31 -> 411.12 | D6: =-cashflow!I31 -> 110.74 | E6: =-cashflow!H31 -> 125.28 | F6: =-cashflow!G31 -> 264.54 | G6: =-cashflow!F31 -> 249.9 | H6: =-cashflow!E31 -> 296.77 | I6: =-cashflow!D31 -> 410.05 | J6: =-cashflow!C31 -> 456.55 | K6: =-cashflow!B31 -> 351.78 | L6: =L4*L7 -> 369.9237 | M6: =M4*M7 -> 391.9123 | N6: =N4*N7 -> 415.20792 | O6: =O4*O7 -> 439.88825 | P6: =P4*P7 -> 466.0356
A7: (% of revenues) | B7: =IF(B4=0,0,B6/B4) -> 0.019702835 | C7: =IF(C4=0,0,C6/C4) -> 0.07656094 | D7: =IF(D4=0,0,D6/D4) -> 0.019743059 | E7: =IF(E4=0,0,E6/E4) -> 0.019970701 | F7: =IF(F4=0,0,F6/F4) -> 0.041925259 | G7: =IF(G4=0,0,G6/G4) -> 0.0347821 | H7: =IF(H4=0,0,H6/H4) -> 0.036282169 | I7: =IF(I4=0,0,I6/I4) -> 0.04721712 | ... K7: =IF(K4=0,0,K6/K4) -> 0.03878197 | L7: =AVERAGE($B$7:$K$7) -> 0.038494098 | M7: =AVERAGE($B$7:$K$7) -> 0.038494098 | N7: =AVERAGE($B$7:$K$7) -> 0.038494098 | O7: =AVERAGE($B$7:$K$7) -> 0.038494098 | P7: =AVERAGE($B$7:$K$7) -> 0.038494098
A8: Depreciation | B8: =PL!K21 -> 72.83 | C8: =PL!J21 -> 75.43 | D8: =PL!I21 -> 102.5 | E8: =PL!H21 -> 108.83 | F8: =PL!G21 -> 129.93 | G8: =PL!F21 -> 143.4 | H8: =PL!E21 -> 160.39 | I8: =PL!D21 -> 188.29 | J8: =PL!C21 -> 208.86 | K8: =PL!B21 -> 250.93 | L8: =Assumption!L23 -> 288.7643 | M8: =Assumption!M23 -> 332.30313 | N8: =Assumption!N23 -> 382.40657 | O8: =Assumption!O23 -> 440.06443 | P8: =Assumption!P23 -> 506.41573
A9: (Depreceiation Rate %) | B9: =IF(B5=0,0,B8/B5) -> 0 | C9: =IF(C5=0,0,C8/C5) -> 0.11807893 | D9: =IF(D5=0,0,D8/D5) -> 0.10318827 | E9: =IF(E5=0,0,E8/E5) -> 0.10561098 | F9: =IF(F5=0,0,F8/F5) -> 0.12534005 | G9: =IF(G5=0,0,G8/G5) -> 0.12642381 | H9: =IF(H5=0,0,H8/H5) -> 0.13312473 | I9: =IF(I5=0,0,I8/I5) -> 0.13458899 | ... P9: =IF(P5=0,0,P8/P5) -> 0.2292497
A10: Ending PP&E | B10: =Bal.sheet!B18 -> 638.81 | C10: =Bal.sheet!C18 -> 993.33 | D10: =Bal.sheet!D18 -> 1030.48 | E10: =Bal.sheet!E18 -> 1036.62 | F10: =Bal.sheet!F18 -> 1134.28 | G10: =Bal.sheet!G18 -> 1204.81 | H10: =Bal.sheet!H18 -> 1399 | I10: =Bal.sheet!I18 -> 1661.97 | ... K10: =Bal.sheet!K18 -> 2035.62 | L10: =L5+L6-L8 -> 2116.7794 | M10: =M5+M6-M8 -> 2176.3886 | N10: =N5+N6-N8 -> 2209.1899 | O10: =O5+O6-O8 -> 2209.0137 | P10: =P5+P6-P8 -> 2168.6336

Sheet ratios
A1: RATIO | B1: 2016 | C1: 2017 | D1: 2018 | E1: 2019 | F1: 2020 | G1: 2021 | H1: 2022 | I1: 2023 | J1: 2024 | K1: 2025
A2: Liquidity Ratios
A3: Current Ratio | B3: =Assumption!B66/Assumption!B71 -> 1.0342694 | C3: =Assumption!C66/Assumption!C71 -> 0.93303905 | D3: =Assumption!D66/Assumption!D71 -> 1.0840275 | E3: =Assumption!E66/Assumption!E71 -> 1.1332485 | F3: =Assumption!F66/Assumption!F71 -> 1.4306168 | G3: =Assumption!G66/Assumption!G71 -> 1.2679423 | H3: =Assumption!H66/Assumption!H71 -> 0.9595796 | I3: =Assumption!I66/Assumption!I71 -> 0.84767951 | ... K3: =Assumption!K66/Assumption!K71 -> 0.76578657
A4: Quick Ratio | B4: =(Assumption!B66-Assumption!B61)/Assumption!B71 -> 0.48549523 | C4: =(Assumption!C66-Assumption!C61)/Assumption!C71 -> 0.40077095 | D4: =(Assumption!D66-Assumption!D61)/Assumption!D71 -> 0.47058516 | E4: =(Assumption!E66-Assumption!E61)/Assumption!E71 -> 0.53954766 | F4: =(Assumption!F66-Assumption!F61)/Assumption!F71 -> 0.81571268 | G4: =(Assumption!G66-Assumption!G61)/Assumption!G71 -> 0.67408789 | H4: =(Assumption!H66-Assumption!H61)/Assumption!H71 -> 0.35186958 | I4: =(Assumption!I66-Assumption!I61)/Assumption!I71 -> 0.31807402 | ... K4: =(Assumption!K66-Assumption!K61)/Assumption!K71 -> 0.33724698
A5: Profitability Ratios
A6: Gross Margin | B6: =Assumption!B21/Assumption!B7 -> 0.23542048 | C6: =Assumption!C21/Assumption!C7 -> 0.25469921 | D6: =Assumption!D21/Assumption!D7 -> 0.25965276 | E6: =Assumption!E21/Assumption!E7 -> 0.25740927 | F6: =Assumption!F21/Assumption!F7 -> 0.24114024 | G6: =Assumption!G21/Assumption!G7 -> 0.24814574 | H6: =Assumption!H21/Assumption!H7 -> 0.25057292 | I6: =Assumption!I21/Assumption!I7 -> 0.23158613 | ... K6: =Assumption!K21/Assumption!K7 -> 0.22734745
A7: Operating Margin | B7: =Assumption!B17/Assumption!B7 -> 0.2507886 | C7: =Assumption!C17/Assumption!C7 -> 0.24019576 | D7: =Assumption!D17/Assumption!D7 -> 0.23728465 | E7: =Assumption!E17/Assumption!E7 -> 0.23574747 | F7: =Assumption!F17/Assumption!F7 -> 0.23532962 | G7: =Assumption!G17/Assumption!G7 -> 0.22916848 | H7: =Assumption!H17/Assumption!H7 -> 0.229184 | I7: =Assumption!I17/Assumption!I7 -> 0.21493272 | ... K7: =Assumption!K17/Assumption!K7 -> 0.20473602
A8: Net Margin | B8: =Assumption!B33/Assumption!B7 -> 0.16836261 | C8: =Assumption!C33/Assumption!C7 -> 0.18575203 | D8: =Assumption!D33/Assumption!D7 -> 0.19024334 | E8: =Assumption!E33/Assumption!E7 -> 0.20175632 | F8: =Assumption!F33/Assumption!F7 -> 0.19437778 | G8: =Assumption!G33/Assumption!G7 -> 0.18763584 | H8: =Assumption!H33/Assumption!H7 -> 0.17463959 | I8: =Assumption!I33/Assumption!I7 -> 0.15880785 | ... K8: =Assumption!K33/Assumption!K7 -> 0.15502754
A9: ROE | B9: =Assumption!B33/Assumption!B47 -> 0.29633939 | C9: =Assumption!C33/Assumption!C47 -> 0.27310355 | D9: =Assumption!D33/Assumption!D47 -> 0.25578562 | E9: =Assumption!E33/Assumption!E47 -> 0.31838683 | F9: =Assumption!F33/Assumption!F47 -> 0.27109918 | G9: =Assumption!G33/Assumption!G47 -> 0.25620731 | H9: =Assumption!H33/Assumption!H47 -> 0.2444529 | I9: =Assumption!I33/Assumption!I47 -> 0.21999943 | ... K9: =Assumption!K33/Assumption!K47 -> 0.18916276
A10: ROA | B10: =Assumption!B33/Assumption!B78 -> 0.28375589 | C10: =Assumption!C33/Assumption!C78 -> 0.25019159 | D10: =Assumption!D33/Assumption!D78 -> 0.23669589 | E10: =Assumption!E33/Assumption!E78 -> 0.29142528 | F10: =Assumption!F33/Assumption!F78 -> 0.2591995 | G10: =Assumption!G33/Assumption!G78 -> 0.24542778 | H10: =Assumption!H33/Assumption!H78 -> 0.22104375 | I10: =Assumption!I33/Assumption!I78 -> 0.19858118 | ... K10: =Assumption!K33/Assumption!K78 -> 0.17850505
A11: ROCE | B11: =Assumption!B17/(Assumption!B78-Assumption!B71) -> 0.64739479 | C11: =Assumption!C17/(Assumption!C78-Assumption!C71) -> 0.45057168 | D11: =Assumption!D17/(Assumption!D78-Assumption!D71) -> 0.3944338 | E11: =Assumption!E17/(Assumption!E78-Assumption!E71) -> 0.47605706 | F11: =Assumption!F17/(Assumption!F78-Assumption!F71) -> 0.43286577 | G11: =Assumption!G17/(Assumption!G78-Assumption!G71) -> 0.44964631 | H11: =Assumption!H17/(Assumption!H78-Assumption!H71) -> 0.42293908 | I11: =Assumption!I17/(Assumption!I78-Assumption!I71) -> 0.40219671 | ... K11: =Assumption!K17/(Assumption!K78-Assumption!K71) -> 0.3815149
A12: Leverage Ratios
A13: Debt-Equity | B13: =Assumption!B49/Assumption!B47 -> 0.028190635 | C13: =Assumption!C49/Assumption!C47 -> 0.077572255 | D13: =Assumption!D49/Assumption!D47 -> 0.067806835 | E13: =Assumption!E49/Assumption!E47 -> 0.078073584 | F13: =Assumption!F49/Assumption!F47 -> 0.032934505 | G13: =Assumption!G49/Assumption!G47 -> 0.033363506 | H13: =Assumption!H49/Assumption!H47 -> 0.095530767 | I13: =Assumption!I49/Assumption!I47 -> 0.097895936 | ... K13: =Assumption!K49/Assumption!K47 -> 0.05101781
A14: Interest Coverage | B14: =Assumption!B17/Assumption!B19 -> 133.12671 | C14: =Assumption!C17/Assumption!C19 -> 79.592113 | D14: =Assumption!D17/Assumption!D19 -> 61.603929 | E14: =Assumption!E17/Assumption!E19 -> 49.547315 | F14: =Assumption!F17/Assumption!F19 -> 77.910223 | G14: =Assumption!G17/Assumption!G19 -> 184.5744 | H14: =Assumption!H17/Assumption!H19 -> 100.75736 | I14: =Assumption!I17/Assumption!I19 -> 40.369204 | ... K14: =Assumption!K17/Assumption!K19 -> 18.622816
A15: Efficiency Ratios
A16: Inventory Turnover | B16: =Assumption!B15/Assumption!B61 -> 6.6288583 | C16: =Assumption!C15/Assumption!C61 -> 6.8187128 | D16: =Assumption!D15/Assumption!D61 -> 6.1501724 | E16: =Assumption!E15/Assumption!E61 -> 6.5310274 | F16: =Assumption!F15/Assumption!F61 -> 6.0290679 | G16: =Assumption!G15/Assumption!G61 -> 5.0930118 | H16: =Assumption!H15/Assumption!H61 -> 5.1107063 | I16: =Assumption!I15/Assumption!I61 -> 5.5871692 | ... K16: =Assumption!K15/Assumption!K61 -> 5.5923591
A17: Receivable Turnover | B17: =Assumption!B7/Assumption!B63 -> 12.946207 | C17: =Assumption!C7/Assumption!C63 -> 16.138125 | D17: =Assumption!D7/Assumption!D63 -> 17.685598 | E17: =Assumption!E7/Assumption!E63 -> 14.516062 | F17: =Assumption!F7/Assumption!F63 -> 16.805021 | G17: =Assumption!G7/Assumption!G63 -> 26.17494 | H17: =Assumption!H7/Assumption!H63 -> 18.057397 | I17: =Assumption!I7/Assumption!I63 -> 15.519673 | ... K17: =Assumption!K7/Assumption!K63 -> 15.081771
A18: Payable Turnover | B18: =Assumption!B10/Assumption!B69 -> 2.0083018 | C18: =Assumption!C10/Assumption!C69 -> 2.0060582 | D18: =Assumption!D10/Assumption!D69 -> 2.1110289 | E18: =Assumption!E10/Assumption!E69 -> 2.1921801 | F18: =Assumption!F10/Assumption!F69 -> 2.1299416 | G18: =Assumption!G10/Assumption!G69 -> 1.7872415 | H18: =Assumption!H10/Assumption!H69 -> 1.8678152 | I18: =Assumption!I10/Assumption!I69 -> 1.801405 | ... K18: =Assumption!K10/Assumption!K69 -> 1.4630853
A19: Asset Turnover | B19: =Assumption!B7/Assumption!B78 -> 1.6853855 | C19: =Assumption!C7/Assumption!C78 -> 1.3469117 | D19: =Assumption!D7/Assumption!D78 -> 1.2441744 | E19: =Assumption!E7/Assumption!E78 -> 1.4444419 | F19: =Assumption!F7/Assumption!F78 -> 1.3334831 | G19: =Assumption!G7/Assumption!G78 -> 1.3080005 | H19: =Assumption!H7/Assumption!H78 -> 1.2657139 | I19: =Assumption!I7/Assumption!I78 -> 1.2504494 | ... K19: =Assumption!K7/Assumption!K78 -> 1.1514409
A20: Dividend Payout | B20: =Assumption!B34/Assumption!B33 -> 0.46152504 | C20: =Assumption!C34/Assumption!C33 -> 0.22041482 | D20: =Assumption!D34/Assumption!D33 -> 0.203659 | E20: =Assumption!E34/Assumption!E33 -> 0.17472816 | F20: =Assumption!F34/Assumption!F33 -> 0.1994968 | G20: =Assumption!G34/Assumption!G33 -> 0.22392436 | H20: =Assumption!H34/Assumption!H33 -> 0 | I20: =Assumption!I34/Assumption!I33 -> 0 | ... K20: =Assumption!K34/Assumption!K33 -> 0

Sheet beta
A1: Date | B1: Sensex | C1: Dabour | D1: Market Return | E1: Return on dabour | F1: Beta
A2: 40546 | B2: 20561.05 | C2: 100.7
A3: 40547 | B3: 20498.72 | C3: 102.75 | D3: -0.00304 | E3: 0.02015 | F3: =SLOPE(E3:E3719,D3:D3719) -> 0.51563123
A4: 40548 | B4: 20301.1 | C4: 103.05 | D4: -0.00969 | E4: 0.00292
A5: 40549 | B5: 20184.74 | C5: 101.35 | D5: -0.00575 | E5: -0.01663
A6: 40550 | B6: 19691.81 | C6: 100.1 | D6: -0.02472 | E6: -0.01241
A7: 40553 | B7: 19224.12 | C7: 101.3 | D7: -0.02404 | E7: 0.01192
A8: 40554 | B8: 19196.34 | C8: 102.85 | D8: -0.00145 | E8: 0.01519
A9: 40555 | B9: 19534.1 | C9: 101.75 | D9: 0.01744 | E9: -0.01075
A10: 40556 | B10: 19182.82 | C10: 100.8 | D10: -0.01815 | E10: -0.00938
A11: 40557 | B11: 18860.44 | C11: 100.75 | D11: -0.01695 | E11: -0.0005
A12: 40560 | B12: 18882.25 | C12: 99.1 | D12: 0.00116 | E12: -0.01651
A13: 40561 | B13: 19092.05 | C13: 101.25 | D13: 0.01105 | E13: 0.02146
A14: 40562 | B14: 18978.32 | C14: 100.25 | D14: -0.00597 | E14: -0.00993
A15: 40563 | B15: 19046.54 | C15: 99.6 | D15: 0.00359 | E15: -0.0065
... A3719: 46022 | B3719: 85220.6 | C3719: 503.3 | D3719: 0.00642 | E3719: 0.01532

Sheet Historicial beta
B2: Anticipated period | J2: Adjusted period
A4: Date | B4: Sensex | C4: Dabour | D4: Market Return | E4: Return on dabour | H4: Date | I4: Sensex | J4: Dabour | K4: Market Return | L4: Return on dabour | P4: Date | Q4: Sensex | R4: Dabour | S4: Market Return | T4: Return on dabour
A5: 42661 | B5: 28050.88 | C5: 275.15 | D5: 0.01874 | E5: 0.01243 | H5: 42683 | I5: 27252.53 | J5: 297.65 | K5: -0.01235 | L5: 0.0005 | P5: 42614 | Q5: 28423.48 | R5: 293.9 | S5: -0.00101 | T5: 0.01095
A6: 42662 | B6: 27984.37 | C6: 277.2 | D6: -0.00237 | E6: 0.00742 | H6: 42684 | I6: 27517.68 | J6: 296.6 | K6: 0.00968 | L6: -0.00353 | P6: 42615 | Q6: 28532.11 | R6: 296.7 | S6: 0.00381 | T6: 0.00948
A7: 42663 | B7: 28129.84 | C7: 280 | D7: 0.00518 | E7: 0.01005 | H7: 42685 | I7: 26818.82 | J7: 281.15 | K7: -0.02572 | L7: -0.0535 | P7: 42619 | Q7: 28978.02 | R7: 299.7 | S7: 0.01551 | T7: 0.01006
A8: 42664 | B8: 28077.18 | C8: 284.1 | D8: -0.00187 | E8: 0.01454 | H8: 42689 | I8: 26304.63 | J8: 270.35 | K8: -0.01936 | L8: -0.03917 | P8: 42620 | Q8: 28926.36 | R8: 297.05 | S8: -0.00178 | T8: -0.00888
A9: 42667 | B9: 28179.08 | C9: 283.35 | D9: 0.00362 | E9: -0.00264 | H9: 42690 | I9: 26298.69 | J9: 275.25 | K9: -0.00023 | L9: 0.01796 | P9: 42621 | Q9: 29045.28 | R9: 298.6 | S9: 0.0041 | T9: 0.0052
A10: 42668 | B10: 28091.42 | C10: 284.45 | D10: -0.00312 | E10: 0.00387 | H10: 42691 | I10: 26227.62 | J10: 276.6 | K10: -0.00271 | L10: 0.00489 | P10: 42622 | Q10: 28797.25 | R10: 293.7 | S10: -0.00858 | T10: -0.01655
A11: 42669 | B11: 27836.51 | C11: 296.4 | D11: -0.00912 | E11: 0.04115 | H11: 42692 | I11: 26150.24 | J11: 277.65 | K11: -0.00295 | L11: 0.00379 | P11: 42625 | Q11: 28353.54 | R11: 290.2 | S11: -0.01553 | T11: -0.01199
A12: 42670 | B12: 27915.9 | C12: 289.25 | D12: 0.00285 | E12: -0.02442 | H12: 42695 | I12: 25765.14 | J12: 275.75 | K12: -0.01484 | L12: -0.00687 | P12: 42627 | Q12: 28372.23 | R12: 292.65 | S12: 0.00066 | T12: 0.00841
A13: 42671 | B13: 27941.51 | C13: 290.9 | D13: 0.00092 | E13: 0.00569 | H13: 42696 | I13: 25960.78 | J13: 275.7 | K13: 0.00756 | L13: -0.00018 | P13: 42628 | Q13: 28412.89 | R13: 292.85 | S13: 0.00143 | T13: 0.00068
A14: 42673 | B14: 27930.21 | C14: 292.2 | D14: -0.0004 | E14: 0.00446 | H14: 42697 | I14: 26051.81 | J14: 280.6 | K14: 0.0035 | L14: 0.01762 | P14: 42629 | Q14: 28599.03 | R14: 292.8 | S14: 0.00653 | T14: -0.00017
A15: 42675 | B15: 27876.61 | C15: 290.05 | D15: -0.00192 | E15: -0.00739 | H15: 42698 | I15: 25860.17 | J15: 277.1 | K15: -0.00738 | L15: -0.01255 | P15: 42632 | Q15: 28634.5 | R15: 293.9 | S15: 0.00124 | T15: 0.00375
A16: 42676 | B16: 27527.22 | C16: 294.3 | D16: -0.01261 | E16: 0.01455 | H16: 42699 | I16: 26316.34 | J16: 276.05 | K16: 0.01749 | L16: -0.0038 | P16: 42633 | Q16: 28523.2 | R16: 291.15 | S16: -0.00389 | T16: -0.0094
... A19: 42681 | B19: 27458.99 | C19: 296.8 | D19: 0.00675 | E19: -0.00118 | H19: 42704 | I19: 26652.81 | J19: 283.35 | K19: 0.00976 | L19: 0.02194 | P19: 42636 | Q19: 28668.22 | R19: 282.7 | S19: -0.00365 | T19: -0.01178
A20: 42682 | B20: 27591.14 | C20: 297.5 | D20: 0.0048 | E20: 0.00236 | P20: 42639 | Q20: 28294.28 | R20: 281.3 | S20: -0.01313 | T20: -0.00496
P21: 42640 | Q21: 28223.7 | R21: 282 | S21: -0.0025 | T21: 0.00249
B22: Average Return | C22: =AVERAGE(E5:E20) -> 0.005658125 | D22: =AVERAGE(D5:D20) -> 0.000138125 | I22: Average Return | J22: =AVERAGE(L5:L19) -> -0.00325 | K22: =AVERAGE(K5:K19) -> -0.0023073333 | P22: 42641 | Q22: 28292.81 | R22: 277.4 | S22: 0.00245 | T22: -0.01645
B23: Alpha | C23: =INTERCEPT(E5:E20,D5:D20) -> 0.0057422721 | I23: Alpha | J23: =INTERCEPT(L5:L19,K5:K19) -> -0.00048232946 | P23: 42642 | Q23: 27827.53 | R23: 270.05 | S23: -0.01658 | T23: -0.02685
B24: Beta | C24: =SLOPE(E5:E20,D5:D20) -> -0.6092096 | I24: Beta | J24: =SLOPE(L5:L19,K5:K19) -> 1.1995105 | P24: 42643 | Q24: 27865.96 | R24: 271.3 | S24: 0.00138 | T24: 0.00462
P25: 42646 | Q25: 28243.29 | R25: 276.2 | S25: 0.01345 | T25: 0.0179
P26: 42647 | Q26: 28334.55 | R26: 280.05 | S26: 0.00323 | T26: 0.01384
P27: 42648 | Q27: 28220.98 | R27: 282.9 | S27: -0.00402 | T27: 0.01013
P28: 42649 | Q28: 28106.21 | R28: 285.9 | S28: -0.00408 | T28: 0.01055
P29: 42650 | Q29: 28061.14 | R29: 284 | S29: -0.0016 | T29: -0.00667
P30: 42653 | Q30: 28082.34 | R30: 285.55 | S30: 0.00076 | T30: 0.00544
P31: 42656 | Q31: 27643.11 | R31: 282.9 | S31: -0.01576 | T31: -0.00932
P32: 42657 | Q32: 27673.6 | R32: 279.7 | S32: 0.0011 | T32: -0.01138
P33: 42660 | Q33: 27529.97 | R33: 271.75 | S33: -0.0052 | T33: -0.02884
R36: Average Return | S36: =AVERAGE(T5:T33) -> -0.0023244828 | T36: =AVERAGE(S5:S33) -> -0.0011355172
R37: Alpha | S37: =INTERCEPT(T5:T33,S5:S33) -> -0.0013552973
R38: Beta | S38: =SLOPE(T5:T33,S5:S33) -> 0.85351892

Sheet Fundamental beta
A2: Debt to capital | B2: Debt to equity | C2: Levered Beta | D2: Unlev beta *(1+debt to equity % *(1-tax rate)))
A4: 0 | B4: 0 | C4: =$B$14*(1+B4*(1-B16)) -> 0.51563123
A5: 0.1 | B5: =A5/90% -> 0.11111111 | C5: =$B$14*(1+B5*(1-B17)) -> 0.57292359
A6: 0.25 | B6: =A6/75% -> 0.33333333 | C6: =$B$14*(1+B6*(1-D18)) -> 0.68750831
A7: 0.35 | B7: =A7/65% -> 0.53846154 | C7: =$B$14*(1+B7*(1-D19)) -> 0.79327882
A8: 0.5 | B8: =A8/50% -> 1 | C8: =$B$14*(1+B8*(1-D20)) -> 1.0312625
A9: 0.75 | B9: =A9/25% -> 3 | C9: =$B$14*(1+B9*(1-D21)) -> 2.0625249
A12: Years | B12: 2016 | C12: 2017 | D12: 2018 | E12: 2019 | F12: 2020 | G12: 2021 | H12: 2022 | I12: 2023 | J12: 2024 | K12: 2025
A13: DEBT to Equity | B13: =Bal.sheet!K11/Bal.sheet!K8 -> 0.05101781 | C13: =Bal.sheet!J11/Bal.sheet!J8 -> 0.11220802 | D13: =Bal.sheet!I11/Bal.sheet!I8 -> 0.097895936 | E13: =Bal.sheet!H11/Bal.sheet!H8 -> 0.095530767 | F13: =Bal.sheet!G11/Bal.sheet!G8 -> 0.033363506 | G13: =Bal.sheet!F11/Bal.sheet!F8 -> 0.032934505 | H13: =Bal.sheet!E11/Bal.sheet!E8 -> 0.078073584 | I13: =Bal.sheet!D11/Bal.sheet!D8 -> 0.067806835 | J13: =Bal.sheet!C11/Bal.sheet!C8 -> 0.077572255 | K13: =Bal.sheet!B11/Bal.sheet!B8 -> 0.028190635
A14: Unlevered Beta | B14: 0.51563123
A15: Levered Beta | B15: =$B$14*(1+B13*(1-B16)) -> 0.53630132 | C15: =$B$14*(1+C13*(1-C16)) -> 0.55959497 | D15: =$B$14*(1+D13*(1-D16)) -> 0.55359842 | E15: =$B$14*(1+E13*(1-E16)) -> 0.55279008 | F15: =$B$14*(1+F13*(1-F16)) -> 0.5276386 | G15: =$B$14*(1+G13*(1-G16)) -> 0.52958927 | H15: =$B$14*(1+H13*(1-H16)) -> 0.54784318 | I15: =$B$14*(1+I13*(1-I16)) -> 0.54249055 | ... K15: =$B$14*(1+K13*(1-K16)) -> 0.52700719 | L15: Unle beta x(1+debt to equity*(1-tax rate))
A16: Tax rate | B16: =Assumption!B27 -> 0.21425559 | C16: =Assumption!C27 -> 0.2401437 | D16: =Assumption!D27 -> 0.2478498 | E16: =Assumption!E27 -> 0.24563807 | F16: =Assumption!F27 -> 0.30202986 | G16: =Assumption!G27 -> 0.17807178 | H16: =Assumption!H27 -> 0.19984602 | I16: =Assumption!I27 -> 0.23178594 | ... K16: =Assumption!K27 -> 0.21739275

Sheet Accounting beta
A1: ROCE%
A2: Years | B2: Dabour India | C2: Average | E2: Dabur ROA
A3: 2025 | B3: =Assumption!K17/(Assumption!K78-Assumption!K71) -> 0.3815149 | C3: =AVERAGE(B3:B3) -> 0.3815149 | D3: ROA | E3: =Assumption!K33/Assumption!K78 -> 0.17850505
A4: 2024 | B4: =Assumption!J17/(Assumption!J78-Assumption!J71) -> 0.39094303 | C4: =AVERAGE(B4:B4) -> 0.39094303 | E4: =Assumption!J33/Assumption!J78 -> 0.19469483
A5: 2023 | B5: =Assumption!I17/(Assumption!I78-Assumption!I71) -> 0.40219671 | C5: =AVERAGE(B5:B5) -> 0.40219671 | E5: =Assumption!I33/Assumption!I78 -> 0.19858118
A6: 2022 | B6: =Assumption!H17/(Assumption!H78-Assumption!H71) -> 0.42293908 | C6: =AVERAGE(B6:B6) -> 0.42293908 | E6: =Assumption!H33/Assumption!H78 -> 0.22104375
A7: 2021 | B7: =Assumption!G17/(Assumption!G78-Assumption!G71) -> 0.44964631 | C7: =AVERAGE(B7:B7) -> 0.44964631 | E7: =Assumption!G33/Assumption!G78 -> 0.24542778
A8: 2020 | B8: =Assumption!F17/(Assumption!F78-Assumption!F71) -> 0.43286577 | C8: =AVERAGE(B8:B8) -> 0.43286577 | E8: =Assumption!F33/Assumption!F78 -> 0.2591995
A9: 2019 | B9: =Assumption!E17/(Assumption!E78-Assumption!E71) -> 0.47605706 | C9: =AVERAGE(B9:B9) -> 0.47605706 | E9: =Assumption!E33/Assumption!E78 -> 0.29142528
A10: 2018 | B10: =Assumption!D17/(Assumption!D78-Assumption!D71) -> 0.3944338 | C10: =AVERAGE(B10:B10) -> 0.3944338 | E10: =Assumption!D33/Assumption!D78 -> 0.23669589
A11: 2017 | B11: =Assumption!C17/(Assumption!C78-Assumption!C71) -> 0.45057168 | C11: =AVERAGE(B11:B11) -> 0.45057168 | E11: =Assumption!C33/Assumption!C78 -> 0.25019159
A12: 2016 | B12: =Assumption!B17/(Assumption!B78-Assumption!B71) -> 0.64739479 | C12: =AVERAGE(B12:B12) -> 0.64739479 | E12: =Assumption!B33/Assumption!B78 -> 0.28375589
B14: =VAR(B3:B12) -> 0.0059951241
B15: =COVAR(B3:B12,C3:C12) -> 0.0053956117
B16: =IF(B14=0,0,B15/B14) -> 0.9

Sheet WACC
A1: weighted average cost of capital
A2: INPUT | C2: Values | E2: Cost of Equity
A3: Risk Free Premium | B3: Rf | C3: 0.0669 | E3: Risk free rate (Rf) | F3: =C3 -> 0.0669
A4: Beta | B4: B | C4: =beta!F3 -> 0.51563123 | E4: Beta (Historical) | F4: =beta!F3 -> 0.51563123
A5: Market Return | B5: MR | C5: 0.12 | E5: Market risk premium (MRP) | F5: =C5-C3 -> 0.0531
A6: Cost of Equity | B6: Ke | C6: =C3+C4*(C5-C3) -> 0.094280019 | E6: Cost of Equity (Ke = Rf + β×MRP) | F6: =C6 -> 0.094280019
A7: Interest Expense | C7: =Assumption!K19 -> 99.58
A8: Total Debt | C8: =Assumption!K49 -> 378.72 | E8: Cost of Debt
A9: Cost of Debt | B9: Kd | C9: =C7/C8 -> 0.26293832 | E9: Interest Expense (INR Cr) | F9: =Assumption!K19 -> 99.58
A10: Tax Rate | B10: t | C10: =Assumption!K27 -> 0.21739275 | E10: Total Debt (INR Cr) | F10: =Assumption!K49 -> 378.72
A11: Total Equity | C11: =Assumption!K45+Assumption!K46 -> 7423.29 | E11: Cost of Debt (Kd = Interest/Debt) | F11: =IF(F10=0,0,F9/F10) -> 0.26293832
